<?xml version="1.0" encoding="UTF-8" ?>
<robot name="sysmap">
    <material name="black">
        <color rgba="0.24 0.2 0.21 1" />
    </material>
    <material name="white">
        <color rgba="0.9 0.9 0.9 1" />
    </material>
    <material name="whiteT">
        <color rgba="0.9 0.9 0.9 0.9" />
    </material>
    <material name="yellow">
        <color rgba="1 1 0 1" />
    </material>
    <link name="world" />
    <link name="platine">
        <visual>
            <origin rpy="1.57 0.0 0.0" />
            <material name="white" />
            <geometry>
                <mesh filename="package://klampt/meshes/1_Platine_optimized.stl" />
            </geometry>
        </visual>
        <collision>
            <origin rpy="1.57 0.0 0.0" />
            <material name="white" />
            <geometry>
                <mesh filename="package://klampt/meshes/1_Platine_convexHull.stl" />
            </geometry>
        </collision>
        <inertial>
            <mass value="0.1" />
            <origin xyz="0 0 0" rpy="0 0 0" />
            <inertia ixx="0.03" iyy="0.03" izz="0.03" ixy="0.0" ixz="0.0" iyz="0.0" />
        </inertial>
    </link>
    <link name="aileron">
        <visual>
            <origin rpy="1.57 0.0 0.0" />
            <material name="white" />
            <geometry>
                <mesh filename="package://klampt/meshes/2_SupportAileron_optimized.stl" />
            </geometry>
        </visual>
        <collision>
            <origin rpy="1.57 0.0 0.0" />
            <material name="white" />
            <geometry>
                <mesh filename="package://klampt/meshes/2_SupportAileron_convexHull.stl" />
            </geometry>
        </collision>
        <inertial>
            <mass value="0.1" />
            <origin xyz="0 0 0" rpy="0 0 0" />
            <inertia ixx="0.03" iyy="0.03" izz="0.03" ixy="0.0" ixz="0.0" iyz="0.0" />
        </inertial>
    </link>
    <link name="aileron_camera">
        <visual>
            <origin rpy="1.57 0.0 0.0" />
            <material name="black" />
            <geometry>
                <mesh filename="package://klampt/meshes/2_SupportAileron_camera_optimized.stl" />
            </geometry>
        </visual>
        <collision>
            <origin rpy="1.57 0.0 0.0" />
            <material name="black" />
            <geometry>
                <mesh filename="package://klampt/meshes/2_SupportAileron_camera_convexHull.stl" />
            </geometry>
        </collision>
        <inertial>
            <mass value="0.1" />
            <origin xyz="0 0 0" rpy="0 0 0" />
            <inertia ixx="0.03" iyy="0.03" izz="0.03" ixy="0.0" ixz="0.0" iyz="0.0" />
        </inertial>
    </link>
    <link name="stockage_liquide">
        <visual>
            <origin rpy="1.57 0.0 -3.6652" />
            <material name="whiteT" />
            <geometry>
                <mesh filename="package://klampt/meshes/3_ZoneStockage_liquide_optimized.stl" />
            </geometry>
        </visual>
        <collision>
            <origin rpy="1.57 0.0 -3.6652" />
            <material name="whiteT" />
            <geometry>
                <mesh filename="package://klampt/meshes/3_ZoneStockage_liquide_convexHull.stl" />
            </geometry>
        </collision>
        <inertial>
            <mass value="0.1" />
            <origin xyz="0 0 0" rpy="0 0 0" />
            <inertia ixx="0.03" iyy="0.03" izz="0.03" ixy="0.0" ixz="0.0" iyz="0.0" />
        </inertial>
    </link>
    <link name="stockage_liquide2">
        <visual>
            <origin rpy="1.57 0.0 -3.6652" />
            <material name="whiteT" />
            <geometry>
                <mesh filename="package://klampt/meshes/3_ZoneStockage_liquide_optimized.stl" />
            </geometry>
        </visual>
        <collision>
            <origin rpy="1.57 0.0 -3.6652" />
            <material name="whiteT" />
            <geometry>
                <mesh filename="package://klampt/meshes/3_ZoneStockage_liquide_convexHull.stl" />
            </geometry>
        </collision>
        <inertial>
            <mass value="0.1" />
            <origin xyz="0 0 0" rpy="0 0 0" />
            <inertia ixx="0.03" iyy="0.03" izz="0.03" ixy="0.0" ixz="0.0" iyz="0.0" />
        </inertial>
    </link>
    <link name="stockage_liquide3">
        <visual>
            <origin rpy="1.57 0.0 -3.6652" />
            <material name="whiteT" />
            <geometry>
                <mesh filename="package://klampt/meshes/3_ZoneStockage_liquide_optimized.stl" />
            </geometry>
        </visual>
        <collision>
            <origin rpy="1.57 0.0 -3.6652" />
            <material name="whiteT" />
            <geometry>
                <mesh filename="package://klampt/meshes/3_ZoneStockage_liquide_convexHull.stl" />
            </geometry>
        </collision>
        <inertial>
            <mass value="0.1" />
            <origin xyz="0 0 0" rpy="0 0 0" />
            <inertia ixx="0.03" iyy="0.03" izz="0.03" ixy="0.0" ixz="0.0" iyz="0.0" />
        </inertial>
    </link>
    <link name="electrique">
        <visual>
            <origin rpy="1.57 0.0 0.0" />
            <material name="black" />
            <geometry>
                <mesh filename="package://klampt/meshes/5_ZoneElec_optimized.stl" />
            </geometry>
        </visual>
        <collision>
            <origin rpy="1.57 0.0 0.0" />
            <material name="black" />
            <geometry>
                <mesh filename="package://klampt/meshes/5_ZoneElec_convexHull.stl" />
            </geometry>
        </collision>
        <inertial>
            <mass value="0.1" />
            <origin xyz="0 0 0" rpy="0 0 0" />
            <inertia ixx="0.03" iyy="0.03" izz="0.03" ixy="0.0" ixz="0.0" iyz="0.0" />
        </inertial>
    </link>
    <link name="batterie">
        <visual>
            <origin rpy="1.57 0.0 0.0" />
            <material name="black" />
            <geometry>
                <mesh filename="package://klampt/meshes/6_ZoneBatterie.stl" />
            </geometry>
        </visual>
        <collision>
            <origin rpy="1.57 0.0 0.0" />
            <material name="black" />
            <geometry>
                <mesh filename="package://klampt/meshes/6_ZoneBatterie.stl" />
            </geometry>
        </collision>
        <inertial>
            <mass value="0.1" />
            <origin xyz="0 0 0" rpy="0 0 0" />
            <inertia ixx="0.03" iyy="0.03" izz="0.03" ixy="0.0" ixz="0.0" iyz="0.0" />
        </inertial>
    </link>
    <link name="base">
        <visual>
            <origin rpy="1.57 0.0 0.0" />
            <material name="yellow" />
            <geometry>
                <mesh filename="package://klampt/meshes/7_1_scara_base_optimized.stl" />
            </geometry>
        </visual>
        <collision>
            <origin rpy="1.57 0.0 0.0" />
            <material name="yellow" />
            <geometry>
                <mesh filename="package://klampt/meshes/7_1_scara_base_convexHull.stl" />
            </geometry>
        </collision>
        <inertial>
            <mass value="0.1" />
            <origin xyz="0 0 0" rpy="0 0 0" />
            <inertia ixx="0.03" iyy="0.03" izz="0.03" ixy="0.0" ixz="0.0" iyz="0.0" />
        </inertial>
    </link>
    <link name="colonne">
        <visual>
            <origin rpy="1.57 0.0 0.0" />
            <material name="black" />
            <geometry>
                <mesh filename="package://klampt/meshes/7_2_scara_colonne_optimized.stl" />
            </geometry>
        </visual>
        <collision>
            <origin rpy="1.57 0.0 0.0" />
            <material name="black" />
            <geometry>
                <mesh filename="package://klampt/meshes/7_2_scara_colonne_convexHull.stl" />
            </geometry>
        </collision>
        <inertial>
            <mass value="0.1" />
            <origin xyz="0 0 0" rpy="0 0 0" />
            <inertia ixx="0.03" iyy="0.03" izz="0.03" ixy="0.0" ixz="0.0" iyz="0.0" />
        </inertial>
    </link>
    <link name="interne">
        <visual>
            <origin rpy="1.57 0.0 0.0" />
            <material name="white" />
            <geometry>
                <mesh filename="package://klampt/meshes/7_3_scara_interne_optimized.stl" />
            </geometry>
        </visual>
        <collision>
            <origin rpy="1.57 0.0 0.0" />
            <material name="white" />
            <geometry>
                <mesh filename="package://klampt/meshes/7_3_scara_interne_convexHull.stl" />
            </geometry>
        </collision>
        <inertial>
            <mass value="0.1" />
            <origin xyz="0 0 0" rpy="0 0 0" />
            <inertia ixx="0.03" iyy="0.03" izz="0.03" ixy="0.0" ixz="0.0" iyz="0.0" />
        </inertial>
    </link>
    <link name="externe">
        <visual>
            <origin rpy="1.57 0.0 0.0" />
            <material name="yellow" />
            <geometry>
                <mesh filename="package://klampt/meshes/7_4_scara_externe_optimized.stl" />
            </geometry>
        </visual>
        <collision>
            <origin rpy="1.57 0.0 0.0" />
            <material name="yellow" />
            <geometry>
                <mesh filename="package://klampt/meshes/7_4_scara_externe_convexHull.stl" />
            </geometry>
        </collision>
        <inertial>
            <mass value="0.1" />
            <origin xyz="0 0 0" rpy="0 0 0" />
            <inertia ixx="0.03" iyy="0.03" izz="0.03" ixy="0.0" ixz="0.0" iyz="0.0" />
        </inertial>
    </link>
    <link name="poignet">
        <visual>
            <origin rpy="1.57 0.0 0.0" />
            <material name="black" />
            <geometry>
                <mesh filename="package://klampt/meshes/7_5_scara_poignet_optimized.stl" />
            </geometry>
        </visual>
        <collision>
            <origin rpy="1.57 0.0 0.0" />
            <material name="black" />
            <geometry>
                <mesh filename="package://klampt/meshes/7_5_scara_poignet_convexHull.stl" />
            </geometry>
        </collision>
        <inertial>
            <mass value="0.1" />
            <origin xyz="0 0 0" rpy="0 0 0" />
            <inertia ixx="0.03" iyy="0.03" izz="0.03" ixy="0.0" ixz="0.0" iyz="0.0" />
        </inertial>
    </link>
    <link name="verin">
        <visual>
            <origin rpy="1.57 0.0 0.0" />
            <material name="white" />
            <geometry>
                <mesh filename="package://klampt/meshes/7_6_scara_verin_optimized.stl" />
            </geometry>
        </visual>
        <collision>
            <origin rpy="1.57 0.0 0.0" />
            <material name="white" />
            <geometry>
                <mesh filename="package://klampt/meshes/7_6_scara_verin_convexHull.stl" />
            </geometry>
        </collision>
        <inertial>
            <mass value="0.1" />
            <origin xyz="0 0 0" rpy="0 0 0" />
            <inertia ixx="0.03" iyy="0.03" izz="0.03" ixy="0.0" ixz="0.0" iyz="0.0" />
        </inertial>
    </link>
    <link name="pince_base">
        <visual>
            <origin rpy="1.57 0.0 0.0" />
            <material name="black" />
            <geometry>
                <mesh filename="package://klampt/meshes/7_7_scara_pince_base_optimized.stl" />
            </geometry>
        </visual>
        <collision>
            <origin rpy="1.57 0.0 0.0" />
            <material name="black" />
            <geometry>
                <mesh filename="package://klampt/meshes/7_7_scara_pince_base_convexHull.stl" />
            </geometry>
        </collision>
        <inertial>
            <mass value="0.1" />
            <origin xyz="0 0 0" rpy="0 0 0" />
            <inertia ixx="0.03" iyy="0.03" izz="0.03" ixy="0.0" ixz="0.0" iyz="0.0" />
        </inertial>
    </link>
    <link name="doigt1">
        <visual>
            <origin xyz="0.0 0.0 0.0" rpy="1.57 -2.094 0.0" />
            <material name="yellow" />
            <geometry>
                <mesh filename="package://klampt/meshes/7_7_scara_pince_doigt_optimized.stl" />
            </geometry>
        </visual>
        <collision>
            <origin xyz="0.0 0.0 0.0" rpy="1.57 -2.094 0.0" />
            <material name="yellow" />
            <geometry>
                <mesh filename="package://klampt/meshes/7_7_scara_pince_doigt_convexHull.stl" />
            </geometry>
        </collision>
        <inertial>
            <mass value="0.1" />
            <origin xyz="0 0 0" rpy="0 0 0" />
            <inertia ixx="0.03" iyy="0.03" izz="0.03" ixy="0.0" ixz="0.0" iyz="0.0" />
        </inertial>
    </link>
    <link name="doigt2">
        <visual>
            <origin xyz="0.0 0.0 0.0" rpy="1.57 -2.094 0.0" />
            <material name="yellow" />
            <geometry>
                <mesh filename="package://klampt/meshes/7_7_scara_pince_doigt_optimized.stl" />
            </geometry>
        </visual>
        <collision>
            <origin xyz="0.0 0.0 0.0" rpy="1.57 -2.094 0.0" />
            <material name="yellow" />
            <geometry>
                <mesh filename="package://klampt/meshes/7_7_scara_pince_doigt_convexHull.stl" />
            </geometry>
        </collision>
        <inertial>
            <mass value="0.1" />
            <origin xyz="0 0 0" rpy="0 0 0" />
            <inertia ixx="0.03" iyy="0.03" izz="0.03" ixy="0.0" ixz="0.0" iyz="0.0" />
        </inertial>
    </link>
    <link name="doigt3">
        <visual>
            <origin xyz="0.0 0.0 0.0" rpy="1.57 -2.094 0.0" />
            <material name="yellow" />
            <geometry>
                <mesh filename="package://klampt/meshes/7_7_scara_pince_doigt_optimized.stl" />
            </geometry>
        </visual>
        <collision>
            <origin xyz="0.0 0.0 0.0" rpy="1.57 -2.094 0.0" />
            <material name="yellow" />
            <geometry>
                <mesh filename="package://klampt/meshes/7_7_scara_pince_doigt_convexHull.stl" />
            </geometry>
        </collision>
        <inertial>
            <mass value="0.1" />
            <origin xyz="0 0 0" rpy="0 0 0" />
            <inertia ixx="0.03" iyy="0.03" izz="0.03" ixy="0.0" ixz="0.0" iyz="0.0" />
        </inertial>
    </link>
    <joint name="world_platine" type="fixed">
        <origin xyz="0.0 0.0 0.0" rpy="0.0 0.0 0.0" />
        <parent link="world" />
        <child link="platine" />
    </joint>
    <joint name="platine_aileron" type="fixed">
        <origin xyz="-0.42 0.042 0.0" rpy="0.0 0.0 0.0" />
        <parent link="platine" />
        <child link="aileron" />
    </joint>
    <joint name="platine_stockageLiquide" type="prismatic">
        <origin xyz="-0.2789 -0.06397 0.0" rpy="0.0 0.0 0.0" />
        <parent link="platine" />
        <child link="stockage_liquide" />
        <axis xyz="0.0 0.0 1.0" />
        <limit lower="0" upper="0" effort="0.0" velocity="0.01" />
    </joint>
    <joint name="platine_stockageLiquide2" type="prismatic">
        <origin xyz="-0.2789 0.05803 0.0" rpy="0.0 0.0 0.0" />
        <parent link="platine" />
        <child link="stockage_liquide2" />
        <axis xyz="0.0 0.0 1.0" />
        <limit lower="0" upper="0" effort="0.0" velocity="0.01" />
    </joint>
    <joint name="platine_stockageLiquide3" type="prismatic">
        <origin xyz="-0.2789 0.18003 0.0" rpy="0.0 0.0 0.0" />
        <parent link="platine" />
        <child link="stockage_liquide3" />
        <axis xyz="0.0 0.0 1.0" />
        <limit lower="0" upper="0" effort="0.0" velocity="0.01" />
    </joint>
    <joint name="platine_electrique" type="fixed">
        <origin xyz="-0.1179 -0.004 0.0" rpy="0.0 0.0 0.0" />
        <parent link="platine" />
        <child link="electrique" />
    </joint>
    <joint name="platine_batterie" type="fixed">
        <origin xyz="0.110 0.276 0.0" rpy="0.0 0.0 0.0" />
        <parent link="platine" />
        <child link="batterie" />
    </joint>
    <joint name="platine_base" type="fixed">
        <origin xyz="0.0 0.0 0.0" rpy="0.0 0.0 0.0" />
        <parent link="platine" />
        <child link="base" />
    </joint>
    <joint name="base_colonne" type="revolute">
        <origin xyz="0.0 0.0 0.03" rpy="0.0 0.0 -5.4044" />
        <parent link="base" />
        <child link="colonne" />
        <axis xyz="0.0 0.0 1.0" />
        <limit lower="0" upper="6.13" effort="0.0" velocity="0.6" />
    </joint>
    <joint name="colonne_interne" type="prismatic">
        <origin xyz="0.0 0.0 0.391" rpy="0.0 0.0 0.0" />
        <parent link="colonne" />
        <child link="interne" />
        <axis xyz="0.0 0.0 1.0" />
        <limit lower="-0.2789" upper="0" effort="0.0" velocity="0.015" />
    </joint>
    <joint name="interne_externe" type="revolute">
        <origin xyz="0.214559 0.163904 -0.005" rpy="0.0 0.0 2.48" />
        <parent link="interne" />
        <child link="externe" />
        <axis xyz="0.0 0.0 -1.0" />
        <limit lower="0.0" upper="4.54" effort="0.0" velocity="0.6" />
    </joint>
    <joint name="externe_poignet" type="revolute">
        <origin xyz="0.29117 0.13275 0.030" rpy="0.0 0.0 2.36" />
        <parent link="externe" />
        <child link="poignet" />
        <axis xyz="0.0 0.0 -1.0" />
        <limit lower="0" upper="6.35" effort="0.0" velocity="0.6" />
    </joint>
    <joint name="poignet_verin" type="prismatic">
        <origin xyz="0.0 0.0 -0.049" rpy="0.0 0.0 0.0" />
        <parent link="poignet" />
        <child link="verin" />
        <axis xyz="0.0 0.0 1.0" />
        <limit lower="-0.15" upper="0.0" effort="0.0" velocity="0.013" />
    </joint>
    <joint name="verin_pince" type="fixed">
        <origin xyz="0.0 0.0 -0.025" rpy="-1.57 0.0 0.74" />
        <parent link="verin" />
        <child link="pince_base" />
    </joint>
    <joint name="pince_doigt1" type="revolute">
        <origin xyz="0.02405 0.07176 0.05466" rpy="0.0 2.094 0.0" />
        <parent link="pince_base" />
        <child link="doigt1" />
        <axis xyz="0.0 0.0 1.0" />
        <limit lower="0" upper="0.8346" effort="0.0" velocity="0.6" />
    </joint>
    <joint name="pince_doigt2" type="revolute">
        <origin xyz="-0.05936 0.07176 -0.0065" rpy="0.0 0.0 0.0" />
        <parent link="pince_base" />
        <child link="doigt2" />
        <axis xyz="0.0 0.0 1.0" />
        <limit lower="0" upper="0.8346" effort="0.0" velocity="0.6" />
        <mimic joint="pince_doigt1" multiplier="1" offset="0" />
    </joint>
    <joint name="pince_doigt3" type="revolute">
        <origin xyz="0.03531 0.07176 -0.04816" rpy="0.0 -2.094 0.0" />
        <parent link="pince_base" />
        <child link="doigt3" />
        <axis xyz="0.0 0.0 1.0" />
        <limit lower="0" upper="0.8346" effort="0.0" velocity="0.6" />
        <mimic joint="pince_doigt1" multiplier="1" offset="0" />
    </joint>
    <joint name="platine_aileron_camera" type="prismatic">
        <origin xyz="-0.42 0.042 -0.05" rpy="0.0 0.0 0.0" />
        <parent link="platine" />
        <child link="aileron_camera" />
        <axis xyz="0.0 0.0 1.0" />
        <limit lower="-0.05" upper="0.08" effort="0.0" velocity="0.0" />
    </joint>
    <!-- <klampt package_root="../../" flip_yz="0" use_vis_geom="1"  freeze_root_link="0" > -->
    <transmission name="trans_platine_stockageLiquide">
        <type>transmission_interface/SimpleTransmission</type>
        <joint name="platine_stockageLiquide">
            <hardwareInterface>hardware_interface/EffortJointInterface</hardwareInterface>
        </joint>
        <actuator name="platine_stockageLiquide_motor">
            <hardwareInterface>hardware_interface/EffortJointInterface</hardwareInterface>
            <mechanicalReduction>1</mechanicalReduction>
        </actuator>
    </transmission>
    <transmission name="trans_platine_stockageLiquide2">
        <type>transmission_interface/SimpleTransmission</type>
        <joint name="platine_stockageLiquide2">
            <hardwareInterface>hardware_interface/EffortJointInterface</hardwareInterface>
        </joint>
        <actuator name="platine_stockageLiquide2_motor">
            <hardwareInterface>hardware_interface/EffortJointInterface</hardwareInterface>
            <mechanicalReduction>1</mechanicalReduction>
        </actuator>
    </transmission>
    <transmission name="trans_platine_stockageLiquide3">
        <type>transmission_interface/SimpleTransmission</type>
        <joint name="platine_stockageLiquide3">
            <hardwareInterface>hardware_interface/EffortJointInterface</hardwareInterface>
        </joint>
        <actuator name="platine_stockageLiquide3_motor">
            <hardwareInterface>hardware_interface/EffortJointInterface</hardwareInterface>
            <mechanicalReduction>1</mechanicalReduction>
        </actuator>
    </transmission>
    <transmission name="trans_base_colonne">
        <type>transmission_interface/SimpleTransmission</type>
        <joint name="base_colonne">
            <hardwareInterface>hardware_interface/EffortJointInterface</hardwareInterface>
        </joint>
        <actuator name="base_colonne_motor">
            <hardwareInterface>hardware_interface/EffortJointInterface</hardwareInterface>
            <mechanicalReduction>1</mechanicalReduction>
        </actuator>
    </transmission>
    <transmission name="trans_colonne_interne">
        <type>transmission_interface/SimpleTransmission</type>
        <joint name="colonne_interne">
            <hardwareInterface>hardware_interface/EffortJointInterface</hardwareInterface>
        </joint>
        <actuator name="colonne_interne_motor">
            <hardwareInterface>hardware_interface/EffortJointInterface</hardwareInterface>
            <mechanicalReduction>1</mechanicalReduction>
        </actuator>
    </transmission>
    <transmission name="trans_interne_externe">
        <type>transmission_interface/SimpleTransmission</type>
        <joint name="interne_externe">
            <hardwareInterface>hardware_interface/EffortJointInterface</hardwareInterface>
        </joint>
        <actuator name="interne_externe_motor">
            <hardwareInterface>hardware_interface/EffortJointInterface</hardwareInterface>
            <mechanicalReduction>1</mechanicalReduction>
        </actuator>
    </transmission>
    <transmission name="trans_externe_poignet">
        <type>transmission_interface/SimpleTransmission</type>
        <joint name="externe_poignet">
            <hardwareInterface>hardware_interface/EffortJointInterface</hardwareInterface>
        </joint>
        <actuator name="externe_poignet_motor">
            <hardwareInterface>hardware_interface/EffortJointInterface</hardwareInterface>
            <mechanicalReduction>1</mechanicalReduction>
        </actuator>
    </transmission>
    <transmission name="trans_poignet_verin">
        <type>transmission_interface/SimpleTransmission</type>
        <joint name="poignet_verin">
            <hardwareInterface>hardware_interface/EffortJointInterface</hardwareInterface>
        </joint>
        <actuator name="poignet_verin_motor">
            <hardwareInterface>hardware_interface/EffortJointInterface</hardwareInterface>
            <mechanicalReduction>1</mechanicalReduction>
        </actuator>
    </transmission>
    <transmission name="trans_pince_doigt1">
        <type>transmission_interface/SimpleTransmission</type>
        <joint name="pince_doigt1">
            <hardwareInterface>hardware_interface/EffortJointInterface</hardwareInterface>
        </joint>
        <actuator name="pince_doigt1_motor">
            <hardwareInterface>hardware_interface/EffortJointInterface</hardwareInterface>
            <mechanicalReduction>1</mechanicalReduction>
        </actuator>
    </transmission>
    <transmission name="trans_pince_doigt2">
        <type>transmission_interface/SimpleTransmission</type>
        <joint name="pince_doigt2">
            <hardwareInterface>hardware_interface/EffortJointInterface</hardwareInterface>
        </joint>
        <actuator name="pince_doigt2_motor">
            <hardwareInterface>hardware_interface/EffortJointInterface</hardwareInterface>
            <mechanicalReduction>1</mechanicalReduction>
        </actuator>
    </transmission>
    <transmission name="trans_pince_doigt3">
        <type>transmission_interface/SimpleTransmission</type>
        <joint name="pince_doigt3">
            <hardwareInterface>hardware_interface/EffortJointInterface</hardwareInterface>
        </joint>
        <actuator name="pince_doigt3_motor">
            <hardwareInterface>hardware_interface/EffortJointInterface</hardwareInterface>
            <mechanicalReduction>1</mechanicalReduction>
        </actuator>
    </transmission>
    <transmission name="trans_platine_aileron_camera">
        <type>transmission_interface/SimpleTransmission</type>
        <joint name="platine_aileron_camera">
            <hardwareInterface>hardware_interface/EffortJointInterface</hardwareInterface>
        </joint>
        <actuator name="platine_aileron_camera_motor">
            <hardwareInterface>hardware_interface/EffortJointInterface</hardwareInterface>
            <mechanicalReduction>1</mechanicalReduction>
        </actuator>
    </transmission>
    <gazebo>
        <plugin name="gazebo_ros_control">
            <robotNamespace>/</robotNamespace>
        </plugin>
    </gazebo>
</robot>

