<?xml version="1.0" encoding="UTF-8" ?>
<!-- V2 : casque hyperion enlevé -->
<robot name="sysmap">
    <link name="world" />
    <link name="platine">
        <visual>
            <origin rpy="1.57 0.0 0.0" />
            <geometry>
                <mesh filename="package://klampt/meshes/1_Platine_optimized.stl" />
            </geometry>
        </visual>
        <collision>
            <origin rpy="1.57 0.0 0.0" />
            <geometry>
                <mesh filename="package://klampt/meshes/1_Platine_convexHull.stl" />
            </geometry>
        </collision>
        <inertial>
            <mass value="0.1" />
            <origin xyz="0 0 0" rpy="0 0 0" />
            <inertia ixx="0.03" iyy="0.03" izz="0.03" ixy="0.0" ixz="0.0" iyz="0.0" />
        </inertial>
    </link>
    <link name="aileron">
        <visual>
            <origin rpy="1.57 0.0 0.0" />
            <geometry>
                <mesh filename="package://klampt/meshes/2_SupportAileron_optimized.stl" />
            </geometry>
        </visual>
        <collision>
            <origin rpy="1.57 0.0 0.0" />
            <geometry>
                <mesh filename="package://klampt/meshes/2_SupportAileron_convexHull.stl" />
            </geometry>
        </collision>
        <inertial>
            <mass value="0.1" />
            <origin xyz="0 0 0" rpy="0 0 0" />
            <inertia ixx="0.03" iyy="0.03" izz="0.03" ixy="0.0" ixz="0.0" iyz="0.0" />
        </inertial>
    </link>
    <link name="stockage">
        <visual>
            <origin rpy="1.57 0.0 0.0" />
            <geometry>
                <mesh filename="package://klampt/meshes/3_ZoneStockageV6_optimized.stl" />
            </geometry>
        </visual>
        <collision>
            <origin rpy="1.57 0.0 0.0" />
            <geometry>
                <mesh filename="package://klampt/meshes/3_ZoneStockageV6_convexHull.stl" />
            </geometry>
        </collision>
        <inertial>
            <mass value="0.1" />
            <origin xyz="0 0 0" rpy="0 0 0" />
            <inertia ixx="0.03" iyy="0.03" izz="0.03" ixy="0.0" ixz="0.0" iyz="0.0" />
        </inertial>
    </link>
    <link name="electrique">
        <visual>
            <origin rpy="1.57 0.0 0.0" />
            <geometry>
                <mesh filename="package://klampt/meshes/5_ZoneElec_optimized.stl" />
            </geometry>
        </visual>
        <collision>
            <origin rpy="1.57 0.0 0.0" />
            <geometry>
                <mesh filename="package://klampt/meshes/5_ZoneElec_convexHull.stl" />
            </geometry>
        </collision>
        <inertial>
            <mass value="0.1" />
            <origin xyz="0 0 0" rpy="0 0 0" />
            <inertia ixx="0.03" iyy="0.03" izz="0.03" ixy="0.0" ixz="0.0" iyz="0.0" />
        </inertial>
    </link>
    <link name="batterie">
        <visual>
            <origin rpy="1.57 0.0 0.0" />
            <geometry>
                <mesh filename="package://klampt/meshes/6_ZoneBatterie.stl" />
            </geometry>
        </visual>
        <collision>
            <origin rpy="1.57 0.0 0.0" />
            <geometry>
                <mesh filename="package://klampt/meshes/6_ZoneBatterie_convexHull.stl" />
            </geometry>
        </collision>
        <inertial>
            <mass value="0.1" />
            <origin xyz="0 0 0" rpy="0 0 0" />
            <inertia ixx="0.03" iyy="0.03" izz="0.03" ixy="0.0" ixz="0.0" iyz="0.0" />
        </inertial>
    </link>
    <link name="base">
        <visual>
            <origin rpy="1.57 0.0 0.0" />
            <geometry>
                <mesh filename="package://klampt/meshes/7_1_scara_base_optimized.stl" />
            </geometry>
        </visual>
        <collision>
            <origin rpy="1.57 0.0 0.0" />
            <geometry>
                <mesh filename="package://klampt/meshes/7_1_scara_base_convexHull.stl" />
            </geometry>
        </collision>
        <inertial>
            <mass value="0.1" />
            <origin xyz="0 0 0" rpy="0 0 0" />
            <inertia ixx="0.03" iyy="0.03" izz="0.03" ixy="0.0" ixz="0.0" iyz="0.0" />
        </inertial>
    </link>
    <link name="colonne">
        <visual>
            <origin rpy="1.57 0.0 0.0" />
            <geometry>
                <mesh filename="package://klampt/meshes/7_2_scara_colonne_optimized.stl" />
            </geometry>
        </visual>
        <collision>
            <origin rpy="1.57 0.0 0.0" />
            <geometry>
                <mesh filename="package://klampt/meshes/7_2_scara_colonne_convexHull.stl" />
            </geometry>
        </collision>
        <inertial>
            <mass value="0.1" />
            <origin xyz="0 0 0" rpy="0 0 0" />
            <inertia ixx="0.03" iyy="0.03" izz="0.03" ixy="0.0" ixz="0.0" iyz="0.0" />
        </inertial>
    </link>
    <link name="interne">
        <visual>
            <origin rpy="1.57 0.0 0.0" />
            <geometry>
                <mesh filename="package://klampt/meshes/7_3_scara_interne_V2_optimized.stl" />
            </geometry>
        </visual>
        <collision>
            <origin rpy="1.57 0.0 0.0" />
            <geometry>
                <mesh filename="package://klampt/meshes/7_3_scara_interne_V2_convexHull.stl" />
            </geometry>
        </collision>
        <inertial>
            <mass value="0.1" />
            <origin xyz="0 0 0" rpy="0 0 0" />
            <inertia ixx="0.03" iyy="0.03" izz="0.03" ixy="0.0" ixz="0.0" iyz="0.0" />
        </inertial>
    </link>
    <link name="externe">
        <visual>
            <origin rpy="1.57 0.0 0.0" />
            <geometry>
                <mesh filename="package://klampt/meshes/7_4_scara_externe_optimized.stl" />
            </geometry>
        </visual>
        <collision>
            <origin rpy="1.57 0.0 0.0" />
            <geometry>
                <mesh filename="package://klampt/meshes/7_4_scara_externe_convexHull.stl" />
            </geometry>
        </collision>
        <inertial>
            <mass value="0.1" />
            <origin xyz="0 0 0" rpy="0 0 0" />
            <inertia ixx="0.03" iyy="0.03" izz="0.03" ixy="0.0" ixz="0.0" iyz="0.0" />
        </inertial>
    </link>
    <link name="poigner">
        <visual>
            <origin rpy="1.57 0.0 0.0" />
            <geometry>
                <mesh filename="package://klampt/meshes/7_5_scara_poigner_optimized.stl" />
            </geometry>
        </visual>
        <collision>
            <origin rpy="1.57 0.0 0.0" />
            <geometry>
                <mesh filename="package://klampt/meshes/7_5_scara_poigner_convexHull.stl" />
            </geometry>
        </collision>
        <inertial>
            <mass value="0.1" />
            <origin xyz="0 0 0" rpy="0 0 0" />
            <inertia ixx="0.03" iyy="0.03" izz="0.03" ixy="0.0" ixz="0.0" iyz="0.0" />
        </inertial>
    </link>
    <link name="verin">
        <visual>
            <origin rpy="1.57 0.0 0.0" />
            <geometry>
                <mesh filename="package://klampt/meshes/7_6_scara_verin_optimized.stl" />
            </geometry>
        </visual>
        <collision>
            <origin rpy="1.57 0.0 0.0" />
            <geometry>
                <mesh filename="package://klampt/meshes/7_6_scara_verin_convexHull.stl" />
            </geometry>
        </collision>
        <inertial>
            <mass value="0.1" />
            <origin xyz="0 0 0" rpy="0 0 0" />
            <inertia ixx="0.03" iyy="0.03" izz="0.03" ixy="0.0" ixz="0.0" iyz="0.0" />
        </inertial>
    </link>
    <link name="pince">
        <visual>
            <origin rpy="1.57 0.0 0.0" />
            <geometry>
                <mesh filename="package://klampt/meshes/7_7_scara_pince_ferme_optimized.stl" />
            </geometry>
        </visual>
        <collision>
            <origin rpy="1.57 0.0 0.0" />
            <geometry>
                <mesh filename="package://klampt/meshes/7_7_scara_pince_ferme_convexHull.stl" />
            </geometry>
        </collision>
        <inertial>
            <mass value="0.1" />
            <origin xyz="0 0 0" rpy="0 0 0" />
            <inertia ixx="0.03" iyy="0.03" izz="0.03" ixy="0.0" ixz="0.0" iyz="0.0" />
        </inertial>
    </link>
    <joint name="world_platine" type="fixed">
        <origin xyz="0.0 0.0 0.0" rpy="0.0 0.0 0.0" />
        <parent link="world" />
        <child link="platine" />
    </joint>
    <joint name="platine_aileron" type="fixed">
        <origin xyz="-0.42 0.042 0.0" rpy="0.0 0.0 0.0" />
        <parent link="platine" />
        <child link="aileron" />
    </joint>
    <joint name="platine_stockage" type="fixed">
        <origin xyz="-0.2789 -0.06397 0.0" rpy="0.0 0.0 0.0" />
        <parent link="platine" />
        <child link="stockage" />
    </joint>
    <joint name="platine_electrique" type="fixed">
        <origin xyz="-0.1179 -0.004 0.0" rpy="0.0 0.0 0.0" />
        <parent link="platine" />
        <child link="electrique" />
    </joint>
    <joint name="platine_batterie" type="fixed">
        <origin xyz="0.110 0.276 0.0" rpy="0.0 0.0 0.0" />
        <parent link="platine" />
        <child link="batterie" />
    </joint>
    <joint name="platine_base" type="fixed">
        <origin xyz="0.0 0.0 0.0" rpy="0.0 0.0 0.0" />
        <parent link="platine" />
        <child link="base" />
    </joint>
    <joint name="base_colonne" type="revolute">
        <origin xyz="0.0 0.0 0.03" rpy="0.0 0.0 0.0" />
        <parent link="base" />
        <child link="colonne" />
        <axis xyz="0.0 0.0 1.0" />
        <limit lower="-6" upper="6" effort="0.0" velocity="0.0" />
    </joint>
    <joint name="colonne_interne" type="prismatic">
        <origin xyz="0.0 0.0 0.391" rpy="0.0 0.0 0.0" />
        <parent link="colonne" />
        <child link="interne" />
        <axis xyz="0.0 0.0 1.0" />
        <limit lower="-0.309" upper="0" effort="0.0" velocity="0.0" />
    </joint>
    <joint name="interne_externe" type="revolute">
        <origin xyz="0.214559 0.163904 -0.005" rpy="0.0 0.0 0.0" />
        <parent link="interne" />
        <child link="externe" />
        <axis xyz="0.0 0.0 1.0" />
        <limit lower="-2.1" upper="2.56" effort="0.0" velocity="0.0" />
    </joint>
    <joint name="externe_poigner" type="revolute">
        <origin xyz="0.29117 0.13275 0.030" rpy="0.0 0.0 0.0" />
        <parent link="externe" />
        <child link="poigner" />
        <axis xyz="0.0 0.0 1.0" />
        <limit lower="-3" upper="3" effort="0.0" velocity="0.0" />
    </joint>
    <joint name="poigner_verin" type="prismatic">
        <origin xyz="0.0 0.0 -0.083" rpy="0.0 0.0 0.0" />
        <parent link="poigner" />
        <child link="verin" />
        <axis xyz="0.0 0.0 1.0" />
        <limit lower="-0.15" upper="0.0" effort="0.0" velocity="0.0" />
    </joint>
    <joint name="verin_pince" type="fixed">
        <origin xyz="0.0 0.0 -0.025" rpy="-1.57 0.0 0.0" />
        <parent link="verin" />
        <child link="pince" />
    </joint>
    <transmission name="trans_base_colonne">
        <type>transmission_interface/SimpleTransmission</type>
        <joint name="base_colonne">
            <hardwareInterface>hardware_interface/EffortJointInterface</hardwareInterface>
        </joint>
        <actuator name="base_colonne_motor">
            <hardwareInterface>hardware_interface/EffortJointInterface</hardwareInterface>
            <mechanicalReduction>1</mechanicalReduction>
        </actuator>
    </transmission>
    <transmission name="trans_colonne_interne">
        <type>transmission_interface/SimpleTransmission</type>
        <joint name="colonne_interne">
            <hardwareInterface>hardware_interface/EffortJointInterface</hardwareInterface>
        </joint>
        <actuator name="colonne_interne_motor">
            <hardwareInterface>hardware_interface/EffortJointInterface</hardwareInterface>
            <mechanicalReduction>1</mechanicalReduction>
        </actuator>
    </transmission>
    <transmission name="trans_interne_externe">
        <type>transmission_interface/SimpleTransmission</type>
        <joint name="interne_externe">
            <hardwareInterface>hardware_interface/EffortJointInterface</hardwareInterface>
        </joint>
        <actuator name="interne_externe_motor">
            <hardwareInterface>hardware_interface/EffortJointInterface</hardwareInterface>
            <mechanicalReduction>1</mechanicalReduction>
        </actuator>
    </transmission>
    <transmission name="trans_externe_poigner">
        <type>transmission_interface/SimpleTransmission</type>
        <joint name="externe_poigner">
            <hardwareInterface>hardware_interface/EffortJointInterface</hardwareInterface>
        </joint>
        <actuator name="externe_poigner_motor">
            <hardwareInterface>hardware_interface/EffortJointInterface</hardwareInterface>
            <mechanicalReduction>1</mechanicalReduction>
        </actuator>
    </transmission>
    <transmission name="trans_poigner_verin">
        <type>transmission_interface/SimpleTransmission</type>
        <joint name="poigner_verin">
            <hardwareInterface>hardware_interface/EffortJointInterface</hardwareInterface>
        </joint>
        <actuator name="poigner_verin_motor">
            <hardwareInterface>hardware_interface/EffortJointInterface</hardwareInterface>
            <mechanicalReduction>1</mechanicalReduction>
        </actuator>
    </transmission>
    <gazebo>
        <plugin name="gazebo_ros_control">
            <robotNamespace>/</robotNamespace>
        </plugin>
    </gazebo>
</robot>

