<?xml version="1.0" encoding="UTF-8"?>
<robot name="sysmap">

    <link name="world"/>
    
    <link name="stockage_boite">
        <visual>
            <geometry>
                <mesh filename="..\meshes\3_ZoneStockage_boite_optimized.stl" scale="0.001 0.001 0.001"/>
            </geometry>
        </visual>
        <collision>
            <geometry>
                <mesh filename="..\meshes\3_ZoneStockage_boite_convexHull.stl" scale="0.001 0.001 0.001"/>
            </geometry>
        </collision>
    </link>


    <link name="stockage_couvercle">
        <visual>
            <geometry>
                <mesh filename="..\meshes\3_ZoneStockage_couvercle_optimized.stl" scale="0.001 0.001 0.001"/>
            </geometry>
        </visual>
        <collision>
            <geometry>
                <mesh filename="..\meshes\3_ZoneStockage_couvercle_convexHull.stl" scale="0.001 0.001 0.001"/>
            </geometry>
        </collision>
    </link>

 <link name="stockage_boite2">
        <visual>
            <geometry>
                <mesh filename="..\meshes\3_ZoneStockage_boite_optimized.stl" scale="0.001 0.001 0.001"/>
            </geometry>
        </visual>
        <collision>
            <geometry>
                <mesh filename="..\meshes\3_ZoneStockage_boite_convexHull.stl" scale="0.001 0.001 0.001"/>
            </geometry>
        </collision>
    </link>


    <link name="stockage_couvercle2">
        <visual>
            <geometry>
                <mesh filename="..\meshes\3_ZoneStockage_couvercle_optimized.stl" scale="0.001 0.001 0.001"/>
            </geometry>
        </visual>
        <collision>
            <geometry>
                <mesh filename="..\meshes\3_ZoneStockage_couvercle_convexHull.stl" scale="0.001 0.001 0.001"/>
            </geometry>
        </collision>
    </link>
  
 <link name="stockage_boite3">
        <visual>
            <geometry>
                <mesh filename="..\meshes\3_ZoneStockage_boite_optimized.stl" scale="0.001 0.001 0.001"/>
            </geometry>
        </visual>
        <collision>
            <geometry>
                <mesh filename="..\meshes\3_ZoneStockage_boite_convexHull.stl" scale="0.001 0.001 0.001"/>
            </geometry>
        </collision>
    </link>


    <link name="stockage_couvercle3">
        <visual>
            <geometry>
                <mesh filename="..\meshes\3_ZoneStockage_couvercle_optimized.stl" scale="0.001 0.001 0.001"/>
            </geometry>
        </visual>
        <collision>
            <geometry>
                <mesh filename="..\meshes\3_ZoneStockage_couvercle_convexHull.stl" scale="0.001 0.001 0.001"/>
            </geometry>
        </collision>
    </link>

    <joint name="world_stockageboite" type="fixed">
        <origin xyz="0.0 0.0 0.0" rpy="0.0 0.0 0.0"/>
        <parent link="world"/>
        <child link="stockage_boite"/>
    </joint>

    <joint name="stockage_boitecouvercle" type="revolute">
        <origin xyz="-0.0185 0.1203 0.1528" rpy="-0.117 0.0 0.0"/>
        <parent link="stockage_boite"/>
        <child link="stockage_couvercle"/>
        <axis xyz="-1.0 0.0 0.0"/>
        <limit lower="0.0" upper="1.453" effort="0.0" velocity="0.0"/>
    </joint>

    <joint name="world_stockageboite2" type="fixed">
        <origin xyz="0.122 0.0 0.0" rpy="0.0 0.0 0.0"/>
        <parent link="world"/>
        <child link="stockage_boite2"/>
    </joint>

    <joint name="stockage_boitecouvercle2" type="revolute">
        <origin xyz="-0.0185 0.1203 0.1528" rpy="-0.117 0.0 0.0"/>
        <parent link="stockage_boite2"/>
        <child link="stockage_couvercle2"/>
        <axis xyz="-1.0 0.0 0.0"/>
        <limit lower="0.0" upper="1.453" effort="0.0" velocity="0.0"/>
    </joint>

    <joint name="world_stockageboite3" type="fixed">
        <origin xyz="0.244 0.0 0.0" rpy="0.0 0.0 0.0"/>
        <parent link="world"/>
        <child link="stockage_boite3"/>
    </joint>

    <joint name="stockage_boitecouvercle3" type="revolute">
        <origin xyz="-0.0185 0.1203 0.1528" rpy="-0.117 0.0 0.0"/>
        <parent link="stockage_boite3"/>
        <child link="stockage_couvercle3"/>
        <axis xyz="-1.0 0.0 0.0"/>
        <limit lower="0.0" upper="1.453" effort="0.0" velocity="0.0"/>
    </joint>

    <klampt package_root="./" flip_yz="1" use_vis_geom="1"  freeze_root_link="0" >
</robot>