<?xml version="1.0" encoding="UTF-8"?>
<!-- V2 : casque hyperion enlevé -->
<robot name="sysmap">

    <link name="world"/>
    
    <link name="platine">
        <visual>
            <origin rpy="1.57 0.0 0.0" />
            <geometry>
                <mesh filename="package://klampt/meshes/1_Platine_optimized.stl"/>
            </geometry>
        </visual>
        <collision>
            <origin rpy="1.57 0.0 0.0" />
            <geometry>
                <mesh filename="package://klampt/meshes/1_Platine_convexHull.stl"/>
            </geometry>
        </collision>
    </link>

    <link name="aileron">
        <visual>
            <origin rpy="1.57 0.0 0.0" />
            <geometry>
                <mesh filename="package://klampt/meshes/2_SupportAileron_optimized.stl"/>
            </geometry>
        </visual>
        <collision>
            <origin rpy="1.57 0.0 0.0" />
            <geometry>
                <mesh filename="package://klampt/meshes/2_SupportAileron_convexHull.stl"/>
            </geometry>
        </collision>
    </link>

    <link name="stockage_boite">
        <visual>
            <origin rpy="1.57 0.0 0.0" />
            <geometry>
                <mesh filename="package://klampt/meshes/3_ZoneStockage_boite_optimized.stl" scale="0.001 0.001 0.001"/>
            </geometry>
        </visual>
        <collision>
            <origin rpy="1.57 0.0 0.0" />
            <geometry>
                <mesh filename="package://klampt/meshes/3_ZoneStockage_boite_convexHull.stl" scale="0.001 0.001 0.001"/>
            </geometry>
        </collision>
    </link>

    <link name="stockage_couvercle">
        <visual>
            <origin rpy="1.57 0.0 0.0" />
            <geometry>
                <mesh filename="package://klampt/meshes/3_ZoneStockage_couvercle_optimized.stl" scale="0.001 0.001 0.001"/>
            </geometry>
        </visual>
        <collision>
            <origin rpy="1.57 0.0 0.0" />
            <geometry>
                <mesh filename="package://klampt/meshes/3_ZoneStockage_couvercle_convexHull.stl" scale="0.001 0.001 0.001"/>
            </geometry>
        </collision>
    </link>

    <link name="stockage_boite2">
        <visual>
            <origin rpy="1.57 0.0 0.0" />
            <geometry>
                <mesh filename="package://klampt/meshes/3_ZoneStockage_boite_optimized.stl" scale="0.001 0.001 0.001"/>
            </geometry>
        </visual>
        <collision>
            <origin rpy="1.57 0.0 0.0" />
            <geometry>
                <mesh filename="package://klampt/meshes/3_ZoneStockage_boite_convexHull.stl" scale="0.001 0.001 0.001"/>
            </geometry>
        </collision>
    </link>

    <link name="stockage_couvercle2">
        <visual>
            <origin rpy="1.57 0.0 0.0" />
            <geometry>
                <mesh filename="package://klampt/meshes/3_ZoneStockage_couvercle_optimized.stl" scale="0.001 0.001 0.001"/>
            </geometry>
        </visual>
        <collision>
            <origin rpy="1.57 0.0 0.0" />
            <geometry>
                <mesh filename="package://klampt/meshes/3_ZoneStockage_couvercle_convexHull.stl" scale="0.001 0.001 0.001"/>
            </geometry>
        </collision>
    </link>

    <link name="stockage_boite3">
        <visual>
            <origin rpy="1.57 0.0 0.0" />
            <geometry>
                <mesh filename="package://klampt/meshes/3_ZoneStockage_boite_optimized.stl" scale="0.001 0.001 0.001"/>
            </geometry>
        </visual>
        <collision>
            <origin rpy="1.57 0.0 0.0" />
            <geometry>
                <mesh filename="package://klampt/meshes/3_ZoneStockage_boite_convexHull.stl" scale="0.001 0.001 0.001"/>
            </geometry>
        </collision>
    </link>

    <link name="stockage_couvercle3">
        <visual>
            <origin rpy="1.57 0.0 0.0" />
            <geometry>
                <mesh filename="package://klampt/meshes/3_ZoneStockage_couvercle_optimized.stl" scale="0.001 0.001 0.001"/>
            </geometry>
        </visual>
        <collision>
            <origin rpy="1.57 0.0 0.0" />
            <geometry>
                <mesh filename="package://klampt/meshes/3_ZoneStockage_couvercle_convexHull.stl" scale="0.001 0.001 0.001"/>
            </geometry>
        </collision>
    </link>

    <link name="electrique">
        <visual>
            <origin rpy="1.57 0.0 0.0" />
            <geometry>
                <mesh filename="package://klampt/meshes/5_ZoneElec_optimized.stl"/>
            </geometry>
        </visual>
        <collision>
            <origin rpy="1.57 0.0 0.0" />
            <geometry>
                <mesh filename="package://klampt/meshes/5_ZoneElec_only_convexHull.stl"/>
            </geometry>
        </collision>
    </link>

    <link name="batterie">
        <visual>
            <origin rpy="1.57 0.0 0.0" />
            <geometry>
                <mesh filename="package://klampt/meshes/6_ZoneBatterie.stl"/>
            </geometry>
        </visual>
        <collision>
            <origin rpy="1.57 0.0 0.0" />
            <geometry>
                <mesh filename="package://klampt/meshes/6_ZoneBatterie_convexHull.stl"/>
            </geometry>
        </collision>
    </link>

    <link name="base">
        <visual>
            <origin rpy="1.57 0.0 0.0" />
            <geometry>
                <mesh filename="package://klampt/meshes/7_1_scara_base_optimized.stl"/>
            </geometry>
        </visual>
        <collision>
            <origin rpy="1.57 0.0 0.0" />
            <geometry>
                <mesh filename="package://klampt/meshes/7_1_scara_base_convexHull.stl"/>
            </geometry>
        </collision>
    </link>

    <link name="colonne">
        <visual>
            <origin rpy="1.57 0.0 0.0" />
            <geometry>
                <mesh filename="package://klampt/meshes/7_2_scara_colonne_optimized.stl"/>
            </geometry>
        </visual>
        <collision>
            <origin rpy="1.57 0.0 0.0" />
            <geometry>
                <mesh filename="package://klampt/meshes/7_2_scara_colonne_convexHull.stl"/>
            </geometry>
        </collision>
    </link>

    <link name="interne">
        <visual>
            <origin rpy="1.57 0.0 0.0" />
            <geometry>
                <mesh filename="package://klampt/meshes/7_3_scara_interne_optimized.stl"/>
            </geometry>
        </visual>
        <collision>
            <origin rpy="1.57 0.0 0.0" />
            <geometry>
                <mesh filename="package://klampt/meshes/7_3_scara_interne_convexHull.stl"/>
            </geometry>
        </collision>
    </link>

    <link name="externe">
        <visual>
            <origin rpy="1.57 0.0 0.0" />
            <geometry>
                <mesh filename="package://klampt/meshes/7_4_scara_externe_optimized.stl"/>
            </geometry>
        </visual>
        <collision>
            <origin rpy="1.57 0.0 0.0" />
            <geometry>
                <mesh filename="package://klampt/meshes/7_4_scara_externe_convexHull.stl"/>
            </geometry>
        </collision>
    </link>

    <link name="poignet">
        <visual>
            <origin rpy="1.57 0.0 0.0" />
            <geometry>
                <mesh filename="package://klampt/meshes/7_5_scara_poignet_optimized.stl"/>
            </geometry>
        </visual>
        <collision>
            <origin rpy="1.57 0.0 0.0" />
            <geometry>
                <mesh filename="package://klampt/meshes/7_5_scara_poignet_convexHull.stl"/>
            </geometry>
        </collision>
    </link>

    <link name="verin">
        <visual>
            <origin rpy="1.57 0.0 0.0" />
            <geometry>
                <mesh filename="package://klampt/meshes/7_6_scara_verin_optimized.stl"/>
            </geometry>
        </visual>
        <collision>
            <origin rpy="1.57 0.0 0.0" />
            <geometry>
                <mesh filename="package://klampt/meshes/7_6_scara_verin_convexHull.stl"/>
            </geometry>
        </collision>
    </link>

    <link name="pince_base">
        <visual>
            <origin rpy="1.57 0.0 0.0" />
            <geometry>
                <mesh filename="package://klampt/meshes/7_7_scara_pince_base_optimized.stl"/>
            </geometry>
        </visual>
        <collision>
            <origin rpy="1.57 0.0 0.0" />
            <geometry>
                <mesh filename="package://klampt/meshes/7_7_scara_pince_base_convexHull.stl"/>
            </geometry>
        </collision>
    </link>

    <link name="doigt1">
        <visual>
            <origin xyz="0.0 0.0 0.0" rpy="1.57 -2.094 0.0"/>
            <geometry>
                <mesh filename="package://klampt/meshes/7_7_scara_pince_doigt_optimized.stl"/>
            </geometry>
        </visual>
        <collision>
            <origin xyz="0.0 0.0 0.0" rpy="1.57 -2.094 0.0"/>
            <geometry>
                <mesh filename="package://klampt/meshes/7_7_scara_pince_doigt_convexHull.stl"/>
            </geometry>
        </collision>
    </link>

    <link name="doigt2">
        <visual>
            <origin xyz="0.0 0.0 0.0" rpy="1.57 -2.094 0.0"/>
            <geometry>
                <mesh filename="package://klampt/meshes/7_7_scara_pince_doigt_optimized.stl"/>
            </geometry>
        </visual>
        <collision>
            <origin xyz="0.0 0.0 0.0" rpy="1.57 -2.094 0.0"/>
            <geometry>
                <mesh filename="package://klampt/meshes/7_7_scara_pince_doigt_convexHull.stl"/>
            </geometry>
        </collision>
    </link>

    <link name="doigt3">
        <visual>
            <origin xyz="0.0 0.0 0.0" rpy="1.57 -2.094 0.0"/>
            <geometry>
                <mesh filename="package://klampt/meshes/7_7_scara_pince_doigt_optimized.stl"/>
            </geometry>
        </visual>
        <collision>
            <origin xyz="0.0 0.0 0.0" rpy="1.57 -2.094 0.0"/>
            <geometry>
                <mesh filename="package://klampt/meshes/7_7_scara_pince_doigt_convexHull.stl"/>
            </geometry>
        </collision>
    </link>

    <joint name="world_platine" type="fixed">
        <origin xyz="0.0 0.0 0.0" rpy="0.0 0.0 0.0"/>
        <parent link="world"/>
        <child link="platine"/>
    </joint>

    <joint name="platine_aileron" type="fixed">
        <origin xyz="-0.42 0.042 0.0" rpy="0.0 0.0 0.0"/>
        <parent link="platine"/>
        <child link="aileron"/>
    </joint>

    <joint name="platine_stockageBoite" type="fixed">
        <origin xyz="-0.2789 -0.06397 0.0" rpy="1.57 0.0 -1.57"/>
        <parent link="platine"/>
        <child link="stockage_boite"/>
    </joint>

    <joint name="stockageBoite_couvercle" type="revolute">
        <origin xyz="-0.0185 0.1203 0.1528" rpy="-0.117 0.0 0.0"/>
        <parent link="stockage_boite"/>
        <child link="stockage_couvercle"/>
        <axis xyz="-1.0 0.0 0.0"/>
        <limit lower="0.0" upper="1.453" effort="0.0" velocity="0.0"/>
    </joint>

    <joint name="platine_stockageBoite2" type="fixed">
        <origin xyz="-0.2789 0.05803 0.0" rpy="1.57 0.0 -1.57"/>
        <parent link="platine"/>
        <child link="stockage_boite2"/>
    </joint>

    <joint name="stockageBoite_couvercle2" type="revolute">
        <origin xyz="-0.0185 0.1203 0.1528" rpy="-0.117 0.0 0.0"/>
        <parent link="stockage_boite2"/>
        <child link="stockage_couvercle2"/>
        <axis xyz="-1.0 0.0 0.0"/>
        <limit lower="0.0" upper="1.453" effort="0.0" velocity="0.0"/>
    </joint>

    <joint name="platine_stockageBoite3" type="fixed">
        <origin xyz="-0.2789 0.18003 0.0" rpy="1.57 0.0 -1.57"/>
        <parent link="platine"/>
        <child link="stockage_boite3"/>
    </joint>

    <joint name="stockageBoite_couvercle3" type="revolute">
        <origin xyz="-0.0185 0.1203 0.1528" rpy="-0.117 0.0 0.0"/>
        <parent link="stockage_boite3"/>
        <child link="stockage_couvercle3"/>
        <axis xyz="-1.0 0.0 0.0"/>
        <limit lower="0.0" upper="1.453" effort="0.0" velocity="0.0"/>
    </joint>

    <joint name="platine_electrique" type="fixed">
        <origin xyz="-0.1179 -0.004 0.0" rpy="0.0 0.0 0.0"/>
        <parent link="platine"/>
        <child link="electrique"/>
    </joint>

    <joint name="platine_batterie" type="fixed">
        <origin xyz="0.110 0.276 0.0" rpy="0.0 0.0 0.0"/>
        <parent link="platine"/>
        <child link="batterie"/>
    </joint>

    <joint name="platine_base" type="fixed">
        <origin xyz="0.0 0.0 0.0" rpy="0.0 0.0 0.0"/>
        <parent link="platine"/>
        <child link="base"/>
    </joint>

    <joint name="base_colonne" type="revolute">
        <origin xyz="0.0 0.0 0.03" rpy="0.0 0.0 -5.4044"/>
        <parent link="base"/>
        <child link="colonne"/>
        <axis xyz="0.0 0.0 1.0"/>
        <limit lower="0" upper="6.35" effort="0.0" velocity="0.0"/>
    </joint>

    <joint name="colonne_interne" type="prismatic">
        <origin xyz="0.0 0.0 0.391" rpy="0.0 0.0 0.0"/>
        <parent link="colonne"/>
        <child link="interne"/>
        <axis xyz="0.0 0.0 1.0"/>
        <limit lower="-0.2995" upper="0" effort="0.0" velocity="0.0"/>
    </joint>

    <joint name="interne_externe" type="revolute">
        <origin xyz="0.214559 0.163904 -0.005" rpy="0.0 0.0 2.56"/>
        <parent link="interne"/>
        <child link="externe"/>
        <axis xyz="0.0 0.0 -1.0"/>
        <limit lower="0.0" upper="4.60" effort="0.0" velocity="0.0"/>
    </joint>

    <joint name="externe_poignet" type="revolute">
        <origin xyz="0.29117 0.13275 0.030" rpy="0.0 0.0 2.36"/>
        <parent link="externe"/>
        <child link="poignet"/>
        <axis xyz="0.0 0.0 -1.0"/>
        <limit lower="0" upper="6.35" effort="0.0" velocity="0.0"/>
    </joint>

    <joint name="poignet_verin" type="prismatic">
        <origin xyz="0.0 0.0 -0.083" rpy="0.0 0.0 0.0"/>
        <parent link="poignet"/>
        <child link="verin"/>
        <axis xyz="0.0 0.0 1.0"/>
        <limit lower="-0.15" upper="0.0" effort="0.0" velocity="0.0"/>
    </joint>

    <joint name="verin_pince" type="fixed">
        <origin xyz="0.0 0.0 -0.025" rpy="-1.57 0.0 0.74"/>
        <parent link="verin"/>
        <child link="pince_base"/>
    </joint>

    <joint name="pince_doigt1" type="revolute">
        <origin xyz="0.02405 0.07176 0.05466" rpy="0.0 2.094 0.0"/>
        <parent link="pince_base"/>
        <child link="doigt1"/>
        <axis xyz="0.0 0.0 1.0"/>
        <limit lower="0" upper="0.8346" effort="0.0" velocity="0.0"/>
    </joint>

    <joint name="pince_doigt2" type="revolute">
        <origin xyz="-0.05936 0.07176 -0.0065" rpy="0.0 0.0 0.0"/>
        <parent link="pince_base"/>
        <child link="doigt2"/>
        <axis xyz="0.0 0.0 1.0"/>
        <limit lower="0" upper="0.8346" effort="0.0" velocity="0.0"/>
        <mimic joint="pince_doigt1" multiplier="1" offset="0"/>
    </joint>

    <joint name="pince_doigt3" type="revolute">
        <origin xyz="0.03531 0.07176 -0.04816" rpy="0.0 -2.094 0.0"/>
        <parent link="pince_base"/>
        <child link="doigt3"/>
        <axis xyz="0.0 0.0 1.0"/>
        <limit lower="0" upper="0.8346" effort="0.0" velocity="0.0"/>
        <mimic joint="pince_doigt1" multiplier="1" offset="0"/>
    </joint>

    <klampt package_root="../../" flip_yz="0" use_vis_geom="1"  freeze_root_link="0" >
</robot>